Workbook

Sheet デイ
A1: コード | B1: 銘柄名（RSS） | C1: 現在値 | D1: 前日比率 | E1: 前日比率2 | F1: VWAP | G1: 当日出来高（RSS） | H1: 20日平均出来高 | I1: RVOL | J1: 補正RVOL | K1: 判定2 | L1: 信用倍率 | M1: PER | N1: PBR | O1: 配当 | P1: 配当率 | Q1: メモ | R1: 0.37847222 | S1: 60 | T1: しきい値 | U1: 1.5
A2: 4014 | B2: =IFERROR(_xll.RssMarket($A2,"銘柄名称"),"") -> カラダノート | C2: =IFERROR(_xll.RssMarket($A2,"現在値"),"") -> 449 | D2: =IFERROR(_xll.RssMarket($A2,"前日比"),"") -> -6 | E2: =IFERROR(_xll.RssMarket($A2,"前日比率"),"") -> -1.32 | F2: =IFERROR(_xll.RssMarket($A2,"出来高加重平均"),"") -> 450.6944 | G2: =IFERROR(_xll.RssMarket($A2,"出来高"),"") -> 7200 | H2: 105375 | I2: =IFERROR(G2/H2,"") -> 0.068327402 | J2: =T20D3[[#This Row],[RVOL]]*$U$2 -> 0.068327402 | K2: =IFERROR(IF(J2>=デイ!$U$1,"〇",""),"") | L2: =IFERROR(_xll.RssMarket($A2,"信用倍率"),"") -> 0 | M2: =IFERROR(_xll.RssMarket($A2,"PER"),"") -> 12.5 | N2: =IFERROR(_xll.RssMarket($A2,"PBR"),"") -> 6.24 | O2: =IFERROR(_xll.RssMarket($A2,"配当"),"") -> 0 | P2: =T20D3[[#This Row],[配当]]/T20D3[[#This Row],[現在値]] -> 0 | R2: 0.38194444 | S2: 30 | T2: 補正係数 300/経過時間（分） | U2: 1
A3: 5596 | B3: =IFERROR(_xll.RssMarket($A3,"銘柄名称"),"") -> アウトルックコンサルティング | C3: =IFERROR(_xll.RssMarket($A3,"現在値"),"") -> 1788 | D3: =IFERROR(_xll.RssMarket($A3,"前日比"),"") -> 1 | E3: =IFERROR(_xll.RssMarket($A3,"前日比率"),"") -> 0.06 | F3: =IFERROR(_xll.RssMarket($A3,"出来高加重平均"),"") -> 1787.5 | G3: =IFERROR(_xll.RssMarket($A3,"出来高"),"") -> 2400 | H3: 12905 | I3: =IFERROR(G3/H3,"") -> 0.18597443 | J3: =T20D3[[#This Row],[RVOL]]*$U$2 -> 0.18597443 | K3: =IFERROR(IF(J3>=デイ!$U$1,"〇",""),"") | L3: =IFERROR(_xll.RssMarket($A3,"信用倍率"),"") -> 0 | M3: =IFERROR(_xll.RssMarket($A3,"PER"),"") -> 14.11 | N3: =IFERROR(_xll.RssMarket($A3,"PBR"),"") -> 4.99 | O3: =IFERROR(_xll.RssMarket($A3,"配当"),"") -> 17 | P3: =T20D3[[#This Row],[配当]]/T20D3[[#This Row],[現在値]] -> 0.00950783 | R3: 0.38541667 | S3: 20
A4: 8136 | B4: =IFERROR(_xll.RssMarket($A4,"銘柄名称"),"") -> サンリオ | C4: =IFERROR(_xll.RssMarket($A4,"現在値"),"") -> 5464 | D4: =IFERROR(_xll.RssMarket($A4,"前日比"),"") -> 700 | E4: =IFERROR(_xll.RssMarket($A4,"前日比率"),"") -> 14.69 | F4: =IFERROR(_xll.RssMarket($A4,"出来高加重平均"),"") -> 5464 | G4: =IFERROR(_xll.RssMarket($A4,"出来高"),"") -> 2381700 | H4: 8534270 | I4: =IFERROR(G4/H4,"") -> 0.27907484 | J4: =T20D3[[#This Row],[RVOL]]*$U$2 -> 0.27907484 | K4: =IFERROR(IF(J4>=デイ!$U$1,"〇",""),"") | L4: =IFERROR(_xll.RssMarket($A4,"信用倍率"),"") -> 31.82 | M4: =IFERROR(_xll.RssMarket($A4,"PER"),"") -> 26.82 | N4: =IFERROR(_xll.RssMarket($A4,"PBR"),"") -> 9.31 | O4: =IFERROR(_xll.RssMarket($A4,"配当"),"") -> 62 | P4: =T20D3[[#This Row],[配当]]/T20D3[[#This Row],[現在値]] -> 0.011346999 | R4: 0.39583333 | S4: 10
A5: 6574 | B5: =IFERROR(_xll.RssMarket($A5,"銘柄名称"),"") -> コンヴァノ | C5: =IFERROR(_xll.RssMarket($A5,"現在値"),"") -> 130 | D5: =IFERROR(_xll.RssMarket($A5,"前日比"),"") -> 3 | E5: =IFERROR(_xll.RssMarket($A5,"前日比率"),"") -> 2.36 | F5: =IFERROR(_xll.RssMarket($A5,"出来高加重平均"),"") -> 127.9115 | G5: =IFERROR(_xll.RssMarket($A5,"出来高"),"") -> 2070000 | H5: 6767215 | I5: =IFERROR(G5/H5,"") -> 0.30588654 | J5: =T20D3[[#This Row],[RVOL]]*$U$2 -> 0.30588654 | K5: =IFERROR(IF(J5>=デイ!$U$1,"〇",""),"") | L5: =IFERROR(_xll.RssMarket($A5,"信用倍率"),"") -> 0 | M5: =IFERROR(_xll.RssMarket($A5,"PER"),"") -> 16.88 | N5: =IFERROR(_xll.RssMarket($A5,"PBR"),"") -> 4.99 | O5: =IFERROR(_xll.RssMarket($A5,"配当"),"") -> 0 | P5: =T20D3[[#This Row],[配当]]/T20D3[[#This Row],[現在値]] -> 0 | R5: 0.41666667 | S5: 5
A6: 5248 | B6: =IFERROR(_xll.RssMarket($A6,"銘柄名称"),"") -> テクノロジーズ | C6: =IFERROR(_xll.RssMarket($A6,"現在値"),"") -> 523 | D6: =IFERROR(_xll.RssMarket($A6,"前日比"),"") -> -15 | E6: =IFERROR(_xll.RssMarket($A6,"前日比率"),"") -> -2.79 | F6: =IFERROR(_xll.RssMarket($A6,"出来高加重平均"),"") -> 521.4175 | G6: =IFERROR(_xll.RssMarket($A6,"出来高"),"") -> 64900 | H6: 168265 | I6: =IFERROR(G6/H6,"") -> 0.38570113 | J6: =T20D3[[#This Row],[RVOL]]*$U$2 -> 0.38570113 | K6: =IFERROR(IF(J6>=デイ!$U$1,"〇",""),"") | L6: =IFERROR(_xll.RssMarket($A6,"信用倍率"),"") -> 0 | M6: =IFERROR(_xll.RssMarket($A6,"PER"),"") -> 17.72 | N6: =IFERROR(_xll.RssMarket($A6,"PBR"),"") -> 6.33 | O6: =IFERROR(_xll.RssMarket($A6,"配当"),"") -> 0 | P6: =T20D3[[#This Row],[配当]]/T20D3[[#This Row],[現在値]] -> 0 | R6: 0.45833333 | S6: 2.5
A7: 3912 | B7: =IFERROR(_xll.RssMarket($A7,"銘柄名称"),"") -> モバイルファクトリー | C7: =IFERROR(_xll.RssMarket($A7,"現在値"),"") -> 1140 | D7: =IFERROR(_xll.RssMarket($A7,"前日比"),"") -> -24 | E7: =IFERROR(_xll.RssMarket($A7,"前日比率"),"") -> -2.06 | F7: =IFERROR(_xll.RssMarket($A7,"出来高加重平均"),"") -> 1154.7619 | G7: =IFERROR(_xll.RssMarket($A7,"出来高"),"") -> 14700 | H7: 35845 | I7: =IFERROR(G7/H7,"") -> 0.41009904 | J7: =T20D3[[#This Row],[RVOL]]*$U$2 -> 0.41009904 | K7: =IFERROR(IF(J7>=デイ!$U$1,"〇",""),"") | L7: =IFERROR(_xll.RssMarket($A7,"信用倍率"),"") -> 26.11 | M7: =IFERROR(_xll.RssMarket($A7,"PER"),"") -> 9.04 | N7: =IFERROR(_xll.RssMarket($A7,"PBR"),"") -> 2.63 | O7: =IFERROR(_xll.RssMarket($A7,"配当"),"") -> 51 | P7: =T20D3[[#This Row],[配当]]/T20D3[[#This Row],[現在値]] -> 0.044736842 | R7: 0.47916667 | S7: 2
A8: 7049 | B8: =IFERROR(_xll.RssMarket($A8,"銘柄名称"),"") -> 識学 | C8: =IFERROR(_xll.RssMarket($A8,"現在値"),"") -> 925 | D8: =IFERROR(_xll.RssMarket($A8,"前日比"),"") -> -1 | E8: =IFERROR(_xll.RssMarket($A8,"前日比率"),"") -> -0.11 | F8: =IFERROR(_xll.RssMarket($A8,"出来高加重平均"),"") -> 926.1445 | G8: =IFERROR(_xll.RssMarket($A8,"出来高"),"") -> 16600 | H8: 29885 | I8: =IFERROR(G8/H8,"") -> 0.55546261 | J8: =T20D3[[#This Row],[RVOL]]*$U$2 -> 0.55546261 | K8: =IFERROR(IF(J8>=デイ!$U$1,"〇",""),"") | L8: =IFERROR(_xll.RssMarket($A8,"信用倍率"),"") -> 0.51 | M8: =IFERROR(_xll.RssMarket($A8,"PER"),"") -> 21.61 | N8: =IFERROR(_xll.RssMarket($A8,"PBR"),"") -> 2.67 | O8: =IFERROR(_xll.RssMarket($A8,"配当"),"") -> 0 | P8: =T20D3[[#This Row],[配当]]/T20D3[[#This Row],[現在値]] -> 0 | R8: 0.54166667 | S8: 1.7
A9: 3825 | B9: =IFERROR(_xll.RssMarket($A9,"銘柄名称"),"") -> リミックスポイント | C9: =IFERROR(_xll.RssMarket($A9,"現在値"),"") -> 233 | D9: =IFERROR(_xll.RssMarket($A9,"前日比"),"") -> -14 | E9: =IFERROR(_xll.RssMarket($A9,"前日比率"),"") -> -5.67 | F9: =IFERROR(_xll.RssMarket($A9,"出来高加重平均"),"") -> 236.7158 | G9: =IFERROR(_xll.RssMarket($A9,"出来高"),"") -> 2127200 | H9: 3573785 | I9: =IFERROR(G9/H9,"") -> 0.59522327 | J9: =T20D3[[#This Row],[RVOL]]*$U$2 -> 0.59522327 | K9: =IFERROR(IF(J9>=デイ!$U$1,"〇",""),"") | L9: =IFERROR(_xll.RssMarket($A9,"信用倍率"),"") -> 0 | M9: =IFERROR(_xll.RssMarket($A9,"PER"),"") -> 16.29 | N9: =IFERROR(_xll.RssMarket($A9,"PBR"),"") -> 1.04 | O9: =IFERROR(_xll.RssMarket($A9,"配当"),"") -> 5 | P9: =T20D3[[#This Row],[配当]]/T20D3[[#This Row],[現在値]] -> 0.021459227
A10: 215A | B10: =IFERROR(_xll.RssMarket($A10,"銘柄名称"),"") -> タイミー | C10: =IFERROR(_xll.RssMarket($A10,"現在値"),"") -> 1191 | D10: =IFERROR(_xll.RssMarket($A10,"前日比"),"") -> -107 | E10: =IFERROR(_xll.RssMarket($A10,"前日比率"),"") -> -8.24 | F10: =IFERROR(_xll.RssMarket($A10,"出来高加重平均"),"") -> 1218.9932 | G10: =IFERROR(_xll.RssMarket($A10,"出来高"),"") -> 3873000 | H10: 5191325 | I10: =IFERROR(G10/H10,"") -> 0.74605231 | J10: =T20D3[[#This Row],[RVOL]]*$U$2 -> 0.74605231 | K10: =IFERROR(IF(J10>=デイ!$U$1,"〇",""),"") | L10: =IFERROR(_xll.RssMarket($A10,"信用倍率"),"") -> 2.69 | M10: =IFERROR(_xll.RssMarket($A10,"PER"),"") -> 50.04 | N10: =IFERROR(_xll.RssMarket($A10,"PBR"),"") -> 8.22 | O10: =IFERROR(_xll.RssMarket($A10,"配当"),"") -> 0 | P10: =T20D3[[#This Row],[配当]]/T20D3[[#This Row],[現在値]] -> 0
A11: 9552 | B11: =IFERROR(_xll.RssMarket($A11,"銘柄名称"),"") -> クオンツ総研ホールディンク | C11: =IFERROR(_xll.RssMarket($A11,"現在値"),"") -> 1048 | D11: =IFERROR(_xll.RssMarket($A11,"前日比"),"") -> -32 | E11: =IFERROR(_xll.RssMarket($A11,"前日比率"),"") -> -2.96 | F11: =IFERROR(_xll.RssMarket($A11,"出来高加重平均"),"") -> 1049.5779 | G11: =IFERROR(_xll.RssMarket($A11,"出来高"),"") -> 428900 | H11: 537790 | I11: =IFERROR(G11/H11,"") -> 0.7975232 | J11: =T20D3[[#This Row],[RVOL]]*$U$2 -> 0.7975232 | K11: =IFERROR(IF(J11>=デイ!$U$1,"〇",""),"") | L11: =IFERROR(_xll.RssMarket($A11,"信用倍率"),"") -> 9.56 | M11: =IFERROR(_xll.RssMarket($A11,"PER"),"") -> 16.04 | N11: =IFERROR(_xll.RssMarket($A11,"PBR"),"") -> 10.75 | O11: =IFERROR(_xll.RssMarket($A11,"配当"),"") -> 6 | P11: =T20D3[[#This Row],[配当]]/T20D3[[#This Row],[現在値]] -> 0.0057251908
A12: 4222 | B12: =IFERROR(_xll.RssMarket($A12,"銘柄名称"),"") -> 児玉化学 | C12: =IFERROR(_xll.RssMarket($A12,"現在値"),"") -> 892 | D12: =IFERROR(_xll.RssMarket($A12,"前日比"),"") -> -60 | E12: =IFERROR(_xll.RssMarket($A12,"前日比率"),"") -> -6.3 | F12: =IFERROR(_xll.RssMarket($A12,"出来高加重平均"),"") -> 909.6489 | G12: =IFERROR(_xll.RssMarket($A12,"出来高"),"") -> 558400 | H12: 679610 | I12: =IFERROR(G12/H12,"") -> 0.82164771 | J12: =T20D3[[#This Row],[RVOL]]*$U$2 -> 0.82164771 | K12: =IFERROR(IF(J12>=デイ!$U$1,"〇",""),"") | L12: =IFERROR(_xll.RssMarket($A12,"信用倍率"),"") -> 0 | M12: =IFERROR(_xll.RssMarket($A12,"PER"),"") -> 0.69 | N12: =IFERROR(_xll.RssMarket($A12,"PBR"),"") -> 0.52 | O12: =IFERROR(_xll.RssMarket($A12,"配当"),"") -> 0 | P12: =T20D3[[#This Row],[配当]]/T20D3[[#This Row],[現在値]] -> 0
A13: 3939 | B13: =IFERROR(_xll.RssMarket($A13,"銘柄名称"),"") -> カナミックネットワーク | C13: =IFERROR(_xll.RssMarket($A13,"現在値"),"") -> 518 | D13: =IFERROR(_xll.RssMarket($A13,"前日比"),"") -> -25 | E13: =IFERROR(_xll.RssMarket($A13,"前日比率"),"") -> -4.6 | F13: =IFERROR(_xll.RssMarket($A13,"出来高加重平均"),"") -> 523.4664 | G13: =IFERROR(_xll.RssMarket($A13,"出来高"),"") -> 202800 | H13: 224360 | I13: =IFERROR(G13/H13,"") -> 0.90390444 | J13: =T20D3[[#This Row],[RVOL]]*$U$2 -> 0.90390444 | K13: =IFERROR(IF(J13>=デイ!$U$1,"〇",""),"") | L13: =IFERROR(_xll.RssMarket($A13,"信用倍率"),"") -> 2.03 | M13: =IFERROR(_xll.RssMarket($A13,"PER"),"") -> 17.92 | N13: =IFERROR(_xll.RssMarket($A13,"PBR"),"") -> 5.28 | O13: =IFERROR(_xll.RssMarket($A13,"配当"),"") -> 9 | P13: =T20D3[[#This Row],[配当]]/T20D3[[#This Row],[現在値]] -> 0.017374517
A14: 339A | B14: =IFERROR(_xll.RssMarket($A14,"銘柄名称"),"") -> プログレス・テクノロジース | C14: =IFERROR(_xll.RssMarket($A14,"現在値"),"") -> 1487 | D14: =IFERROR(_xll.RssMarket($A14,"前日比"),"") -> -55 | E14: =IFERROR(_xll.RssMarket($A14,"前日比率"),"") -> -3.57 | F14: =IFERROR(_xll.RssMarket($A14,"出来高加重平均"),"") -> 1485.9187 | G14: =IFERROR(_xll.RssMarket($A14,"出来高"),"") -> 51700 | H14: 54645 | I14: =IFERROR(G14/H14,"") -> 0.94610669 | J14: =T20D3[[#This Row],[RVOL]]*$U$2 -> 0.94610669 | K14: =IFERROR(IF(J14>=デイ!$U$1,"〇",""),"") | L14: =IFERROR(_xll.RssMarket($A14,"信用倍率"),"") -> 0 | M14: =IFERROR(_xll.RssMarket($A14,"PER"),"") -> 10.51 | N14: =IFERROR(_xll.RssMarket($A14,"PBR"),"") -> 2.12 | O14: =IFERROR(_xll.RssMarket($A14,"配当"),"") -> 30 | P14: =T20D3[[#This Row],[配当]]/T20D3[[#This Row],[現在値]] -> 0.020174849
A15: 9416 | B15: =IFERROR(_xll.RssMarket($A15,"銘柄名称"),"") -> ビジョン | C15: =IFERROR(_xll.RssMarket($A15,"現在値"),"") -> 1293 | D15: =IFERROR(_xll.RssMarket($A15,"前日比"),"") -> -18 | E15: =IFERROR(_xll.RssMarket($A15,"前日比率"),"") -> -1.37 | F15: =IFERROR(_xll.RssMarket($A15,"出来高加重平均"),"") -> 1298.4047 | G15: =IFERROR(_xll.RssMarket($A15,"出来高"),"") -> 422500 | H15: 363260 | I15: =IFERROR(G15/H15,"") -> 1.1630788 | J15: =T20D3[[#This Row],[RVOL]]*$U$2 -> 1.1630788 | K15: =IFERROR(IF(J15>=デイ!$U$1,"〇",""),"") | L15: =IFERROR(_xll.RssMarket($A15,"信用倍率"),"") -> 60.43 | M15: =IFERROR(_xll.RssMarket($A15,"PER"),"") -> 14.87 | N15: =IFERROR(_xll.RssMarket($A15,"PBR"),"") -> 3.32 | O15: =IFERROR(_xll.RssMarket($A15,"配当"),"") -> 50 | P15: =T20D3[[#This Row],[配当]]/T20D3[[#This Row],[現在値]] -> 0.03866976
A16: 9984 | B16: =IFERROR(_xll.RssMarket($A16,"銘柄名称"),"") -> ソフトバンクグループ | C16: =IFERROR(_xll.RssMarket($A16,"現在値"),"") -> 4390 | D16: =IFERROR(_xll.RssMarket($A16,"前日比"),"") -> -427 | E16: =IFERROR(_xll.RssMarket($A16,"前日比率"),"") -> -8.86 | F16: =IFERROR(_xll.RssMarket($A16,"出来高加重平均"),"") -> 4550.2294 | G16: =IFERROR(_xll.RssMarket($A16,"出来高"),"") -> 75769800 | H16: 61468480 | I16: =IFERROR(G16/H16,"") -> 1.232661 | J16: =T20D3[[#This Row],[RVOL]]*$U$2 -> 1.232661 | K16: =IFERROR(IF(J16>=デイ!$U$1,"〇",""),"") | L16: =IFERROR(_xll.RssMarket($A16,"信用倍率"),"") -> 11.82 | M16: =IFERROR(_xll.RssMarket($A16,"PER"),"") -> 7.58 | N16: =IFERROR(_xll.RssMarket($A16,"PBR"),"") -> 1.77 | O16: =IFERROR(_xll.RssMarket($A16,"配当"),"") -> 11 | P16: =T20D3[[#This Row],[配当]]/T20D3[[#This Row],[現在値]] -> 0.0025056948
A17: 6080 | B17: =IFERROR(_xll.RssMarket($A17,"銘柄名称"),"") -> Ｍ＆Ａキャピタルパートナー | C17: =IFERROR(_xll.RssMarket($A17,"現在値"),"") -> 3380 | D17: =IFERROR(_xll.RssMarket($A17,"前日比"),"") -> -135 | E17: =IFERROR(_xll.RssMarket($A17,"前日比率"),"") -> -3.84 | F17: =IFERROR(_xll.RssMarket($A17,"出来高加重平均"),"") -> 3414.007 | G17: =IFERROR(_xll.RssMarket($A17,"出来高"),"") -> 113300 | H17: 90265 | I17: =IFERROR(G17/H17,"") -> 1.255193 | J17: =T20D3[[#This Row],[RVOL]]*$U$2 -> 1.255193 | K17: =IFERROR(IF(J17>=デイ!$U$1,"〇",""),"") | L17: =IFERROR(_xll.RssMarket($A17,"信用倍率"),"") -> 2.78 | M17: =IFERROR(_xll.RssMarket($A17,"PER"),"") -> 14.84 | N17: =IFERROR(_xll.RssMarket($A17,"PBR"),"") -> 2.47 | O17: =IFERROR(_xll.RssMarket($A17,"配当"),"") -> 68.34 | P17: =T20D3[[#This Row],[配当]]/T20D3[[#This Row],[現在値]] -> 0.020218935
A18: 8920 | B18: =IFERROR(_xll.RssMarket($A18,"銘柄名称"),"") -> 東祥 | C18: =IFERROR(_xll.RssMarket($A18,"現在値"),"") -> 929 | D18: =IFERROR(_xll.RssMarket($A18,"前日比"),"") -> 11 | E18: =IFERROR(_xll.RssMarket($A18,"前日比率"),"") -> 1.2 | F18: =IFERROR(_xll.RssMarket($A18,"出来高加重平均"),"") -> 926.1408 | G18: =IFERROR(_xll.RssMarket($A18,"出来高"),"") -> 166100 | H18: 121930 | I18: =IFERROR(G18/H18,"") -> 1.362257 | J18: =T20D3[[#This Row],[RVOL]]*$U$2 -> 1.362257 | K18: =IFERROR(IF(J18>=デイ!$U$1,"〇",""),"") | L18: =IFERROR(_xll.RssMarket($A18,"信用倍率"),"") -> 8.21 | M18: =IFERROR(_xll.RssMarket($A18,"PER"),"") -> 9.79 | N18: =IFERROR(_xll.RssMarket($A18,"PBR"),"") -> 0.93 | O18: =IFERROR(_xll.RssMarket($A18,"配当"),"") -> 10 | P18: =T20D3[[#This Row],[配当]]/T20D3[[#This Row],[現在値]] -> 0.010764263
A19: 6071 | B19: =IFERROR(_xll.RssMarket($A19,"銘柄名称"),"") -> ＩＢＪ | C19: =IFERROR(_xll.RssMarket($A19,"現在値"),"") -> 717 | D19: =IFERROR(_xll.RssMarket($A19,"前日比"),"") -> -14 | E19: =IFERROR(_xll.RssMarket($A19,"前日比率"),"") -> -1.92 | F19: =IFERROR(_xll.RssMarket($A19,"出来高加重平均"),"") -> 721.8145 | G19: =IFERROR(_xll.RssMarket($A19,"出来高"),"") -> 296500 | H19: 208280 | I19: =IFERROR(G19/H19,"") -> 1.4235644 | J19: =T20D3[[#This Row],[RVOL]]*$U$2 -> 1.4235644 | K19: =IFERROR(IF(J19>=デイ!$U$1,"〇",""),"") | L19: =IFERROR(_xll.RssMarket($A19,"信用倍率"),"") -> 16.82 | M19: =IFERROR(_xll.RssMarket($A19,"PER"),"") -> 17.4 | N19: =IFERROR(_xll.RssMarket($A19,"PBR"),"") -> 2.93 | O19: =IFERROR(_xll.RssMarket($A19,"配当"),"") -> 10 | P19: =T20D3[[#This Row],[配当]]/T20D3[[#This Row],[現在値]] -> 0.013947001
A20: 421A | B20: =IFERROR(_xll.RssMarket($A20,"銘柄名称"),"") -> ムービン・ストラテジック・キ | C20: =IFERROR(_xll.RssMarket($A20,"現在値"),"") -> 2519 | D20: =IFERROR(_xll.RssMarket($A20,"前日比"),"") -> -89 | E20: =IFERROR(_xll.RssMarket($A20,"前日比率"),"") -> -3.41 | F20: =IFERROR(_xll.RssMarket($A20,"出来高加重平均"),"") -> 2588.796 | G20: =IFERROR(_xll.RssMarket($A20,"出来高"),"") -> 111300 | H20: 66260 | I20: =IFERROR(G20/H20,"") -> 1.6797465 | J20: =T20D3[[#This Row],[RVOL]]*$U$2 -> 1.6797465 | K20: =IFERROR(IF(J20>=デイ!$U$1,"〇",""),"") -> 〇 | L20: =IFERROR(_xll.RssMarket($A20,"信用倍率"),"") -> 0 | M20: =IFERROR(_xll.RssMarket($A20,"PER"),"") -> 19.33 | N20: =IFERROR(_xll.RssMarket($A20,"PBR"),"") -> 8.07 | O20: =IFERROR(_xll.RssMarket($A20,"配当"),"") -> 0 | P20: =T20D3[[#This Row],[配当]]/T20D3[[#This Row],[現在値]] -> 0
A21: 4389 | B21: =IFERROR(_xll.RssMarket($A21,"銘柄名称"),"") -> プロパティデータバンク | C21: =IFERROR(_xll.RssMarket($A21,"現在値"),"") -> 788 | D21: =IFERROR(_xll.RssMarket($A21,"前日比"),"") -> -56 | E21: =IFERROR(_xll.RssMarket($A21,"前日比率"),"") -> -6.64 | F21: =IFERROR(_xll.RssMarket($A21,"出来高加重平均"),"") -> 808.5185 | G21: =IFERROR(_xll.RssMarket($A21,"出来高"),"") -> 16200 | H21: 8615 | I21: =IFERROR(G21/H21,"") -> 1.8804411 | J21: =T20D3[[#This Row],[RVOL]]*$U$2 -> 1.8804411 | K21: =IFERROR(IF(J21>=デイ!$U$1,"〇",""),"") -> 〇 | L21: =IFERROR(_xll.RssMarket($A21,"信用倍率"),"") -> 0 | M21: =IFERROR(_xll.RssMarket($A21,"PER"),"") -> 12.42 | N21: =IFERROR(_xll.RssMarket($A21,"PBR"),"") -> 2.3 | O21: =IFERROR(_xll.RssMarket($A21,"配当"),"") -> 12 | P21: =T20D3[[#This Row],[配当]]/T20D3[[#This Row],[現在値]] -> 0.015228426
A22: 3661 | B22: =IFERROR(_xll.RssMarket($A22,"銘柄名称"),"") -> エムアップホールディングス | C22: =IFERROR(_xll.RssMarket($A22,"現在値"),"") -> 787 | D22: =IFERROR(_xll.RssMarket($A22,"前日比"),"") -> -13 | E22: =IFERROR(_xll.RssMarket($A22,"前日比率"),"") -> -1.63 | F22: =IFERROR(_xll.RssMarket($A22,"出来高加重平均"),"") -> 793.497 | G22: =IFERROR(_xll.RssMarket($A22,"出来高"),"") -> 973100 | H22: 497645 | I22: =IFERROR(G22/H22,"") -> 1.95541 | J22: =T20D3[[#This Row],[RVOL]]*$U$2 -> 1.95541 | K22: =IFERROR(IF(J22>=デイ!$U$1,"〇",""),"") -> 〇 | L22: =IFERROR(_xll.RssMarket($A22,"信用倍率"),"") -> 22.95 | M22: =IFERROR(_xll.RssMarket($A22,"PER"),"") -> 18 | N22: =IFERROR(_xll.RssMarket($A22,"PBR"),"") -> 6.67 | O22: =IFERROR(_xll.RssMarket($A22,"配当"),"") -> 12.5 | P22: =T20D3[[#This Row],[配当]]/T20D3[[#This Row],[現在値]] -> 0.0158831
A23: 2410 | B23: =IFERROR(_xll.RssMarket($A23,"銘柄名称"),"") -> キャリアデザインセンター | C23: =IFERROR(_xll.RssMarket($A23,"現在値"),"") -> 2445 | D23: =IFERROR(_xll.RssMarket($A23,"前日比"),"") -> -12 | E23: =IFERROR(_xll.RssMarket($A23,"前日比率"),"") -> -0.49 | F23: =IFERROR(_xll.RssMarket($A23,"出来高加重平均"),"") -> 2465.9855 | G23: =IFERROR(_xll.RssMarket($A23,"出来高"),"") -> 55300 | H23: 23690 | I23: =IFERROR(G23/H23,"") -> 2.3343183 | J23: =T20D3[[#This Row],[RVOL]]*$U$2 -> 2.3343183 | K23: =IFERROR(IF(J23>=デイ!$U$1,"〇",""),"") -> 〇 | L23: =IFERROR(_xll.RssMarket($A23,"信用倍率"),"") -> 32.83 | M23: =IFERROR(_xll.RssMarket($A23,"PER"),"") -> 10.09 | N23: =IFERROR(_xll.RssMarket($A23,"PBR"),"") -> 2.77 | O23: =IFERROR(_xll.RssMarket($A23,"配当"),"") -> 125 | P23: =T20D3[[#This Row],[配当]]/T20D3[[#This Row],[現在値]] -> 0.051124744
A24: 4495 | B24: =IFERROR(_xll.RssMarket($A24,"銘柄名称"),"") -> アイキューブドシステムズ | C24: =IFERROR(_xll.RssMarket($A24,"現在値"),"") -> 2408 | D24: =IFERROR(_xll.RssMarket($A24,"前日比"),"") -> -20 | E24: =IFERROR(_xll.RssMarket($A24,"前日比率"),"") -> -0.82 | F24: =IFERROR(_xll.RssMarket($A24,"出来高加重平均"),"") -> 2506.8266 | G24: =IFERROR(_xll.RssMarket($A24,"出来高"),"") -> 37500 | H24: 15795 | I24: =IFERROR(G24/H24,"") -> 2.374169 | J24: =T20D3[[#This Row],[RVOL]]*$U$2 -> 2.374169 | K24: =IFERROR(IF(J24>=デイ!$U$1,"〇",""),"") -> 〇 | L24: =IFERROR(_xll.RssMarket($A24,"信用倍率"),"") -> 0 | M24: =IFERROR(_xll.RssMarket($A24,"PER"),"") -> 16.58 | N24: =IFERROR(_xll.RssMarket($A24,"PBR"),"") -> 4.59 | O24: =IFERROR(_xll.RssMarket($A24,"配当"),"") -> 36 | P24: =T20D3[[#This Row],[配当]]/T20D3[[#This Row],[現在値]] -> 0.014950166
A25: 8789 | B25: =IFERROR(_xll.RssMarket($A25,"銘柄名称"),"") -> フィンテックグローバル | C25: =IFERROR(_xll.RssMarket($A25,"現在値"),"") -> 149 | D25: =IFERROR(_xll.RssMarket($A25,"前日比"),"") -> -9 | E25: =IFERROR(_xll.RssMarket($A25,"前日比率"),"") -> -5.7 | F25: =IFERROR(_xll.RssMarket($A25,"出来高加重平均"),"") -> 147.6061 | G25: =IFERROR(_xll.RssMarket($A25,"出来高"),"") -> 3593000 | H25: 1496970 | I25: =IFERROR(G25/H25,"") -> 2.4001817 | J25: =T20D3[[#This Row],[RVOL]]*$U$2 -> 2.4001817 | K25: =IFERROR(IF(J25>=デイ!$U$1,"〇",""),"") -> 〇 | L25: =IFERROR(_xll.RssMarket($A25,"信用倍率"),"") -> 20.12 | M25: =IFERROR(_xll.RssMarket($A25,"PER"),"") -> 10.64 | N25: =IFERROR(_xll.RssMarket($A25,"PBR"),"") -> 2.63 | O25: =IFERROR(_xll.RssMarket($A25,"配当"),"") -> 5 | P25: =T20D3[[#This Row],[配当]]/T20D3[[#This Row],[現在値]] -> 0.033557047
A26: 3923 | B26: =IFERROR(_xll.RssMarket($A26,"銘柄名称"),"") -> ラクス | C26: =IFERROR(_xll.RssMarket($A26,"現在値"),"") -> 765 | D26: =IFERROR(_xll.RssMarket($A26,"前日比"),"") -> -55 | E26: =IFERROR(_xll.RssMarket($A26,"前日比率"),"") -> -6.71 | F26: =IFERROR(_xll.RssMarket($A26,"出来高加重平均"),"") -> 775.5598 | G26: =IFERROR(_xll.RssMarket($A26,"出来高"),"") -> 6060600 | H26: 2474825 | I26: =IFERROR(G26/H26,"") -> 2.4489004 | J26: =T20D3[[#This Row],[RVOL]]*$U$2 -> 2.4489004 | K26: =IFERROR(IF(J26>=デイ!$U$1,"〇",""),"") -> 〇 | L26: =IFERROR(_xll.RssMarket($A26,"信用倍率"),"") -> 6.73 | M26: =IFERROR(_xll.RssMarket($A26,"PER"),"") -> 22.76 | N26: =IFERROR(_xll.RssMarket($A26,"PBR"),"") -> 11.29 | O26: =IFERROR(_xll.RssMarket($A26,"配当"),"") -> 3.4 | P26: =T20D3[[#This Row],[配当]]/T20D3[[#This Row],[現在値]] -> 0.0044444444
A27: 4496 | B27: =IFERROR(_xll.RssMarket($A27,"銘柄名称"),"") -> コマースＯＮＥＨＬＤＧＳ | C27: =IFERROR(_xll.RssMarket($A27,"現在値"),"") -> 773 | D27: =IFERROR(_xll.RssMarket($A27,"前日比"),"") -> -14 | E27: =IFERROR(_xll.RssMarket($A27,"前日比率"),"") -> -1.78 | F27: =IFERROR(_xll.RssMarket($A27,"出来高加重平均"),"") -> 799.3258 | G27: =IFERROR(_xll.RssMarket($A27,"出来高"),"") -> 8900 | H27: 3375 | I27: =IFERROR(G27/H27,"") -> 2.637037 | J27: =T20D3[[#This Row],[RVOL]]*$U$2 -> 2.637037 | K27: =IFERROR(IF(J27>=デイ!$U$1,"〇",""),"") -> 〇 | L27: =IFERROR(_xll.RssMarket($A27,"信用倍率"),"") -> 0 | M27: =IFERROR(_xll.RssMarket($A27,"PER"),"") -> 11.31 | N27: =IFERROR(_xll.RssMarket($A27,"PBR"),"") -> 2.05 | O27: =IFERROR(_xll.RssMarket($A27,"配当"),"") -> 21 | P27: =T20D3[[#This Row],[配当]]/T20D3[[#This Row],[現在値]] -> 0.027166882
A28: 3696 | B28: =IFERROR(_xll.RssMarket($A28,"銘柄名称"),"") -> セレス | C28: =IFERROR(_xll.RssMarket($A28,"現在値"),"") -> 1617 | D28: =IFERROR(_xll.RssMarket($A28,"前日比"),"") -> -189 | E28: =IFERROR(_xll.RssMarket($A28,"前日比率"),"") -> -10.47 | F28: =IFERROR(_xll.RssMarket($A28,"出来高加重平均"),"") -> 1683.2807 | G28: =IFERROR(_xll.RssMarket($A28,"出来高"),"") -> 557500 | H28: 162100 | I28: =IFERROR(G28/H28,"") -> 3.439235 | J28: =T20D3[[#This Row],[RVOL]]*$U$2 -> 3.439235 | K28: =IFERROR(IF(J28>=デイ!$U$1,"〇",""),"") -> 〇 | L28: =IFERROR(_xll.RssMarket($A28,"信用倍率"),"") -> 26.6 | M28: =IFERROR(_xll.RssMarket($A28,"PER"),"") -> 5.57 | N28: =IFERROR(_xll.RssMarket($A28,"PBR"),"") -> 1.54 | O28: =IFERROR(_xll.RssMarket($A28,"配当"),"") -> 80 | P28: =T20D3[[#This Row],[配当]]/T20D3[[#This Row],[現在値]] -> 0.049474335
A29: 4040 | B29: =IFERROR(_xll.RssMarket($A29,"銘柄名称"),"") -> 南海化学 | C29: =IFERROR(_xll.RssMarket($A29,"現在値"),"") -> 3415 | D29: =IFERROR(_xll.RssMarket($A29,"前日比"),"") -> 30 | E29: =IFERROR(_xll.RssMarket($A29,"前日比率"),"") -> 0.89 | F29: =IFERROR(_xll.RssMarket($A29,"出来高加重平均"),"") -> 3478.173 | G29: =IFERROR(_xll.RssMarket($A29,"出来高"),"") -> 41600 | H29: 11355 | I29: =IFERROR(G29/H29,"") -> 3.6635843 | J29: =T20D3[[#This Row],[RVOL]]*$U$2 -> 3.6635843 | K29: =IFERROR(IF(J29>=デイ!$U$1,"〇",""),"") -> 〇 | L29: =IFERROR(_xll.RssMarket($A29,"信用倍率"),"") -> 0 | M29: =IFERROR(_xll.RssMarket($A29,"PER"),"") -> 3.54 | N29: =IFERROR(_xll.RssMarket($A29,"PBR"),"") -> 0.79 | O29: =IFERROR(_xll.RssMarket($A29,"配当"),"") -> 60 | P29: =T20D3[[#This Row],[配当]]/T20D3[[#This Row],[現在値]] -> 0.017569546
A30: 7089 | B30: =IFERROR(_xll.RssMarket($A30,"銘柄名称"),"") -> フォースタートアップス | C30: =IFERROR(_xll.RssMarket($A30,"現在値"),"") -> 1180 | D30: =IFERROR(_xll.RssMarket($A30,"前日比"),"") -> -41 | E30: =IFERROR(_xll.RssMarket($A30,"前日比率"),"") -> -3.36 | F30: =IFERROR(_xll.RssMarket($A30,"出来高加重平均"),"") -> 1195.4867 | G30: =IFERROR(_xll.RssMarket($A30,"出来高"),"") -> 101700 | H30: 24095 | I30: =IFERROR(G30/H30,"") -> 4.2207927 | J30: =T20D3[[#This Row],[RVOL]]*$U$2 -> 4.2207927 | K30: =IFERROR(IF(J30>=デイ!$U$1,"〇",""),"") -> 〇 | L30: =IFERROR(_xll.RssMarket($A30,"信用倍率"),"") -> 0 | M30: =IFERROR(_xll.RssMarket($A30,"PER"),"") -> 12.77 | N30: =IFERROR(_xll.RssMarket($A30,"PBR"),"") -> 3.22 | O30: =IFERROR(_xll.RssMarket($A30,"配当"),"") -> 0 | P30: =T20D3[[#This Row],[配当]]/T20D3[[#This Row],[現在値]] -> 0
A33: コード | B33: 銘柄名（RSS） | C33: 現在値 | D33: 前日比 | E33: 前日比率 | F33: VWAP | G33: 当日出来高（RSS） | H33: 20日平均出来高 | I33: RVOL | J33: 補正RVOL | K33: 判定2 | L33: 信用倍率 | M33: PER | N33: PBR | O33: 配当 | P33: 配当率 | Q33: メモ
R40: 0.54166667 | S40: 1.7

Sheet 割安チェック 
A1: コード(手入力） | B1: 銘柄名（RSS） | C1: 市場部 | D1: 現在値 | E1: 前日比 | F1: 時価総額 | G1: 株式数 （百万） | H1: PER | I1: EPS | J1: PBR | K1: BPS | L1: ROE | M1: 配当 | N1: 配当率 | O1: スコア③ | P1: スコア⑤ | Q1: Gap比 | R1: 営業利益 率（予） | S1: 成長率 | T1: 現金及び預金（億） | U1: 負債（億） | V1: 総資産 | W1: ネットキャッシュ比率 | X1: 列1
A2: 9104 | B2: =IFERROR(_xll.RssMarket($A2,"銘柄名称"),"") -> 商船三井 | C2: =IFERROR(_xll.RssMarket($A2,"市場部略称"),"") -> 東Ｐ | D2: =IFERROR(_xll.RssMarket($A2,"現在値"),"") -> 5140 | E2: =IFERROR(_xll.RssMarket($A2,"前日比"),"") -> -71 | F2: =IFERROR(_xll.RssMarket($A2,"時価総額"),"") -> 1865169 | G2: =T20D35746[[#This Row],[時価総額]]/T20D35746[[#This Row],[現在値]] -> 362.87335 | H2: =IFERROR(_xll.RssMarket($A2,"PER"),"") -> 8.82 | I2: =T20D35746[[#This Row],[現在値]] / IFERROR(IF(T20D35746[[#This Row],[PER]] > 0, T20D35746[[#This Row],[PER]], 15), 15) -> 582.76644 | J2: =IFERROR(_xll.RssMarket($A2,"PBR"),"") -> 0.68 | K2: =T20D35746[[#This Row],[現在値]]/T20D35746[[#This Row],[PBR]] -> 7558.8235 | L2: =T20D35746[[#This Row],[EPS]]/T20D35746[[#This Row],[BPS]]*100 -> 7.7097506 | M2: =IFERROR(_xll.RssMarket($A2,"配当"),"") -> 200 | N2: =T20D35746[[#This Row],[配当]]/T20D35746[[#This Row],[現在値]] -> 0.038910506 | O2: =ROUND( ((IF(OR(R2="",R2<=0),20,R2)/20) *(L2/15)) /(IFERROR(IF(H2>0,H2,15),15)/15) *100,0) -> 26 | P2: =ROUND( ((IF(OR(R2="",R2<=0),20,R2)/20) *(L2/15) *((MIN(MAX(S2,0),50)/15)+1) *(1+MIN(MAX(IFERROR(IF(W2="",0,W2),0),-30),50)/200)) /(IFERROR(IF(H2>0,H2,15),15)/15) *100,0) -> 22 | Q2: =T20D35746[[#This Row],[スコア⑤]]/T20D35746[[#This Row],[スコア③]] -> 0.84615385 | R2: 5.94 | T2: 1560 | U2: 16900 | V2: 49800 | W2: =(T20D35746[[#This Row],[現金及び預金（億）]]-T20D35746[[#This Row],[負債（億）]])/T20D35746[[#This Row],[総資産]]*100 -> -30.803213 | X2: 優良銘柄
A3: 1724 | B3: =IFERROR(_xll.RssMarket($A3,"銘柄名称"),"") -> シンクレイヤ | C3: =IFERROR(_xll.RssMarket($A3,"市場部略称"),"") -> 東Ｓ | D3: =IFERROR(_xll.RssMarket($A3,"現在値"),"") -> 703 | E3: =IFERROR(_xll.RssMarket($A3,"前日比"),"") -> -30 | F3: =IFERROR(_xll.RssMarket($A3,"時価総額"),"") -> 3475 | G3: =T20D35746[[#This Row],[時価総額]]/T20D35746[[#This Row],[現在値]] -> 4.943101 | H3: =IFERROR(_xll.RssMarket($A3,"PER"),"") -> 6.28 | I3: =T20D35746[[#This Row],[現在値]] / IFERROR(IF(T20D35746[[#This Row],[PER]] > 0, T20D35746[[#This Row],[PER]], 15), 15) -> 111.94268 | J3: =IFERROR(_xll.RssMarket($A3,"PBR"),"") -> 0.53 | K3: =T20D35746[[#This Row],[現在値]]/T20D35746[[#This Row],[PBR]] -> 1326.4151 | L3: =T20D35746[[#This Row],[EPS]]/T20D35746[[#This Row],[BPS]]*100 -> 8.4394904 | M3: =IFERROR(_xll.RssMarket($A3,"配当"),"") -> 28 | N3: =T20D35746[[#This Row],[配当]]/T20D35746[[#This Row],[現在値]] -> 0.039829303 | O3: =ROUND( ((IF(OR(R3="",R3<=0),20,R3)/20) *(L3/15)) /(IFERROR(IF(H3>0,H3,15),15)/15) *100,0) -> 40 | P3: =ROUND( ((IF(OR(R3="",R3<=0),20,R3)/20) *(L3/15) *((MIN(MAX(S3,0),50)/15)+1) *(1+MIN(MAX(IFERROR(IF(W3="",0,W3),0),-30),50)/200)) /(IFERROR(IF(H3>0,H3,15),15)/15) *100,0) -> 37 | Q3: =T20D35746[[#This Row],[スコア⑤]]/T20D35746[[#This Row],[スコア③]] -> 0.925 | R3: 6 | T3: 9.48 | U3: 26.2 | V3: 114 | W3: =(T20D35746[[#This Row],[現金及び預金（億）]]-T20D35746[[#This Row],[負債（億）]])/T20D35746[[#This Row],[総資産]]*100 -> -14.666667
A4: 1605 | B4: =IFERROR(_xll.RssMarket($A4,"銘柄名称"),"") -> ＩＮＰＥＸ | C4: =IFERROR(_xll.RssMarket($A4,"市場部略称"),"") -> 東Ｐ | D4: =IFERROR(_xll.RssMarket($A4,"現在値"),"") -> 3473 | E4: =IFERROR(_xll.RssMarket($A4,"前日比"),"") -> -525 | F4: =IFERROR(_xll.RssMarket($A4,"時価総額"),"") -> 4372979 | G4: =T20D35746[[#This Row],[時価総額]]/T20D35746[[#This Row],[現在値]] -> 1259.1359 | H4: =IFERROR(_xll.RssMarket($A4,"PER"),"") -> 10.37 | I4: =T20D35746[[#This Row],[現在値]] / IFERROR(IF(T20D35746[[#This Row],[PER]] > 0, T20D35746[[#This Row],[PER]], 15), 15) -> 334.90839 | J4: =IFERROR(_xll.RssMarket($A4,"PBR"),"") -> 0.9 | K4: =T20D35746[[#This Row],[現在値]]/T20D35746[[#This Row],[PBR]] -> 3858.8889 | L4: =T20D35746[[#This Row],[EPS]]/T20D35746[[#This Row],[BPS]]*100 -> 8.6788814 | M4: =IFERROR(_xll.RssMarket($A4,"配当"),"") -> 100 | N4: =T20D35746[[#This Row],[配当]]/T20D35746[[#This Row],[現在値]] -> 0.02879355 | O4: =ROUND( ((IF(OR(R4="",R4<=0),20,R4)/20) *(L4/15)) /(IFERROR(IF(H4>0,H4,15),15)/15) *100,0) -> 234 | P4: =ROUND( ((IF(OR(R4="",R4<=0),20,R4)/20) *(L4/15) *((MIN(MAX(S4,0),50)/15)+1) *(1+MIN(MAX(IFERROR(IF(W4="",0,W4),0),-30),50)/200)) /(IFERROR(IF(H4>0,H4,15),15)/15) *100,0) -> 221 | Q4: =T20D35746[[#This Row],[スコア⑤]]/T20D35746[[#This Row],[スコア③]] -> 0.94444444 | R4: 56 | T4: 2417 | U4: 10600 | V4: 73800 | W4: =(T20D35746[[#This Row],[現金及び預金（億）]]-T20D35746[[#This Row],[負債（億）]])/T20D35746[[#This Row],[総資産]]*100 -> -11.088076 | X4: 優良銘柄
A5: 9101 | B5: =IFERROR(_xll.RssMarket($A5,"銘柄名称"),"") -> 日本郵船 | C5: =IFERROR(_xll.RssMarket($A5,"市場部略称"),"") -> 東Ｐ | D5: =IFERROR(_xll.RssMarket($A5,"現在値"),"") -> 5049 | E5: =IFERROR(_xll.RssMarket($A5,"前日比"),"") -> -61 | F5: =IFERROR(_xll.RssMarket($A5,"時価総額"),"") -> 2191778 | G5: =T20D35746[[#This Row],[時価総額]]/T20D35746[[#This Row],[現在値]] -> 434.10141 | H5: =IFERROR(_xll.RssMarket($A5,"PER"),"") -> 9.83 | I5: =T20D35746[[#This Row],[現在値]] / IFERROR(IF(T20D35746[[#This Row],[PER]] > 0, T20D35746[[#This Row],[PER]], 15), 15) -> 513.63174 | J5: =IFERROR(_xll.RssMarket($A5,"PBR"),"") -> 0.74 | K5: =T20D35746[[#This Row],[現在値]]/T20D35746[[#This Row],[PBR]] -> 6822.973 | L5: =T20D35746[[#This Row],[EPS]]/T20D35746[[#This Row],[BPS]]*100 -> 7.5279756 | M5: =IFERROR(_xll.RssMarket($A5,"配当"),"") -> 225 | N5: =T20D35746[[#This Row],[配当]]/T20D35746[[#This Row],[現在値]] -> 0.04456328 | O5: =ROUND( ((IF(OR(R5="",R5<=0),20,R5)/20) *(L5/15)) /(IFERROR(IF(H5>0,H5,15),15)/15) *100,0) -> 20 | P5: =ROUND( ((IF(OR(R5="",R5<=0),20,R5)/20) *(L5/15) *((MIN(MAX(S5,0),50)/15)+1) *(1+MIN(MAX(IFERROR(IF(W5="",0,W5),0),-30),50)/200)) /(IFERROR(IF(H5>0,H5,15),15)/15) *100,0) -> 19 | Q5: =T20D35746[[#This Row],[スコア⑤]]/T20D35746[[#This Row],[スコア③]] -> 0.95 | R5: 5.11 | T5: 1499 | U5: 6200 | V5: 43200 | W5: =(T20D35746[[#This Row],[現金及び預金（億）]]-T20D35746[[#This Row],[負債（億）]])/T20D35746[[#This Row],[総資産]]*100 -> -10.881944 | X5: 優良銘柄
A6: 2931 | B6: =IFERROR(_xll.RssMarket($A6,"銘柄名称"),"") -> ユーグレナ | C6: =IFERROR(_xll.RssMarket($A6,"市場部略称"),"") -> 東Ｐ | D6: =IFERROR(_xll.RssMarket($A6,"現在値"),"") -> 405 | E6: =IFERROR(_xll.RssMarket($A6,"前日比"),"") -> -10 | F6: =IFERROR(_xll.RssMarket($A6,"時価総額"),"") -> 55322 | G6: =T20D35746[[#This Row],[時価総額]]/T20D35746[[#This Row],[現在値]] -> 136.59753 | H6: =IFERROR(_xll.RssMarket($A6,"PER"),"") -> 0 | I6: =T20D35746[[#This Row],[現在値]] / IFERROR(IF(T20D35746[[#This Row],[PER]] > 0, T20D35746[[#This Row],[PER]], 15), 15) -> 27 | J6: =IFERROR(_xll.RssMarket($A6,"PBR"),"") -> 1.8 | K6: =T20D35746[[#This Row],[現在値]]/T20D35746[[#This Row],[PBR]] -> 225 | L6: =T20D35746[[#This Row],[EPS]]/T20D35746[[#This Row],[BPS]]*100 -> 12 | M6: =IFERROR(_xll.RssMarket($A6,"配当"),"") -> 0 | N6: =T20D35746[[#This Row],[配当]]/T20D35746[[#This Row],[現在値]] -> 0 | O6: =ROUND( ((IF(OR(R6="",R6<=0),20,R6)/20) *(L6/15)) /(IFERROR(IF(H6>0,H6,15),15)/15) *100,0) -> 80 | P6: =ROUND( ((IF(OR(R6="",R6<=0),20,R6)/20) *(L6/15) *((MIN(MAX(S6,0),50)/15)+1) *(1+MIN(MAX(IFERROR(IF(W6="",0,W6),0),-30),50)/200)) /(IFERROR(IF(H6>0,H6,15),15)/15) *100,0) -> 80 | Q6: =T20D35746[[#This Row],[スコア⑤]]/T20D35746[[#This Row],[スコア③]] -> 1 | W6: =(T20D35746[[#This Row],[現金及び預金（億）]]-T20D35746[[#This Row],[負債（億）]])/T20D35746[[#This Row],[総資産]]*100 -> #DIV/0!
A7: 3134 | B7: =IFERROR(_xll.RssMarket($A7,"銘柄名称"),"") -> Ｈａｍｅｅ | C7: =IFERROR(_xll.RssMarket($A7,"市場部略称"),"") -> 東Ｓ | D7: =IFERROR(_xll.RssMarket($A7,"現在値"),"") -> 481 | E7: =IFERROR(_xll.RssMarket($A7,"前日比"),"") -> -7 | F7: =IFERROR(_xll.RssMarket($A7,"時価総額"),"") -> 7853 | G7: =T20D35746[[#This Row],[時価総額]]/T20D35746[[#This Row],[現在値]] -> 16.326403 | H7: =IFERROR(_xll.RssMarket($A7,"PER"),"") -> 51.17 | I7: =T20D35746[[#This Row],[現在値]] / IFERROR(IF(T20D35746[[#This Row],[PER]] > 0, T20D35746[[#This Row],[PER]], 15), 15) -> 9.4000391 | J7: =IFERROR(_xll.RssMarket($A7,"PBR"),"") -> 1.57 | K7: =T20D35746[[#This Row],[現在値]]/T20D35746[[#This Row],[PBR]] -> 306.36943 | L7: =T20D35746[[#This Row],[EPS]]/T20D35746[[#This Row],[BPS]]*100 -> 3.068204 | M7: =IFERROR(_xll.RssMarket($A7,"配当"),"") -> 22.5 | N7: =T20D35746[[#This Row],[配当]]/T20D35746[[#This Row],[現在値]] -> 0.046777547 | O7: =ROUND( ((IF(OR(R7="",R7<=0),20,R7)/20) *(L7/15)) /(IFERROR(IF(H7>0,H7,15),15)/15) *100,0) -> 2 | P7: =ROUND( ((IF(OR(R7="",R7<=0),20,R7)/20) *(L7/15) *((MIN(MAX(S7,0),50)/15)+1) *(1+MIN(MAX(IFERROR(IF(W7="",0,W7),0),-30),50)/200)) /(IFERROR(IF(H7>0,H7,15),15)/15) *100,0) -> 2 | Q7: =T20D35746[[#This Row],[スコア⑤]]/T20D35746[[#This Row],[スコア③]] -> 1 | R7: 6.27 | T7: 49.9 | U7: 38.5 | V7: 170 | W7: =(T20D35746[[#This Row],[現金及び預金（億）]]-T20D35746[[#This Row],[負債（億）]])/T20D35746[[#This Row],[総資産]]*100 -> 6.7058824
A8: 3350 | B8: =IFERROR(_xll.RssMarket($A8,"銘柄名称"),"") -> メタプラネット | C8: =IFERROR(_xll.RssMarket($A8,"市場部略称"),"") -> 東Ｓ | D8: =IFERROR(_xll.RssMarket($A8,"現在値"),"") -> 325 | E8: =IFERROR(_xll.RssMarket($A8,"前日比"),"") -> -12 | F8: =IFERROR(_xll.RssMarket($A8,"時価総額"),"") -> 379211 | G8: =T20D35746[[#This Row],[時価総額]]/T20D35746[[#This Row],[現在値]] -> 1166.8031 | H8: =IFERROR(_xll.RssMarket($A8,"PER"),"") -> 0 | I8: =T20D35746[[#This Row],[現在値]] / IFERROR(IF(T20D35746[[#This Row],[PER]] > 0, T20D35746[[#This Row],[PER]], 15), 15) -> 21.666667 | J8: =IFERROR(_xll.RssMarket($A8,"PBR"),"") -> 1.06 | K8: =T20D35746[[#This Row],[現在値]]/T20D35746[[#This Row],[PBR]] -> 306.60377 | L8: =T20D35746[[#This Row],[EPS]]/T20D35746[[#This Row],[BPS]]*100 -> 7.0666667 | M8: =IFERROR(_xll.RssMarket($A8,"配当"),"") -> 0 | N8: =T20D35746[[#This Row],[配当]]/T20D35746[[#This Row],[現在値]] -> 0 | O8: =ROUND( ((IF(OR(R8="",R8<=0),20,R8)/20) *(L8/15)) /(IFERROR(IF(H8>0,H8,15),15)/15) *100,0) -> 163 | P8: =ROUND( ((IF(OR(R8="",R8<=0),20,R8)/20) *(L8/15) *((MIN(MAX(S8,0),50)/15)+1) *(1+MIN(MAX(IFERROR(IF(W8="",0,W8),0),-30),50)/200)) /(IFERROR(IF(H8>0,H8,15),15)/15) *100,0) -> 163 | Q8: =T20D35746[[#This Row],[スコア⑤]]/T20D35746[[#This Row],[スコア③]] -> 1 | R8: 69.12 | T8: 27.7 | U8: 45 | V8: 5507 | W8: =(T20D35746[[#This Row],[現金及び預金（億）]]-T20D35746[[#This Row],[負債（億）]])/T20D35746[[#This Row],[総資産]]*100 -> -0.31414563
A9: 3496 | B9: =IFERROR(_xll.RssMarket($A9,"銘柄名称"),"") -> アズーム | C9: =IFERROR(_xll.RssMarket($A9,"市場部略称"),"") -> 東Ｐ | D9: =IFERROR(_xll.RssMarket($A9,"現在値"),"") -> 4325 | E9: =IFERROR(_xll.RssMarket($A9,"前日比"),"") -> -155 | F9: =IFERROR(_xll.RssMarket($A9,"時価総額"),"") -> 53078 | G9: =T20D35746[[#This Row],[時価総額]]/T20D35746[[#This Row],[現在値]] -> 12.27237 | H9: =IFERROR(_xll.RssMarket($A9,"PER"),"") -> 24.12 | I9: =T20D35746[[#This Row],[現在値]] / IFERROR(IF(T20D35746[[#This Row],[PER]] > 0, T20D35746[[#This Row],[PER]], 15), 15) -> 179.31177 | J9: =IFERROR(_xll.RssMarket($A9,"PBR"),"") -> 7.78 | K9: =T20D35746[[#This Row],[現在値]]/T20D35746[[#This Row],[PBR]] -> 555.9126 | L9: =T20D35746[[#This Row],[EPS]]/T20D35746[[#This Row],[BPS]]*100 -> 32.25539 | M9: =IFERROR(_xll.RssMarket($A9,"配当"),"") -> 126 | N9: =T20D35746[[#This Row],[配当]]/T20D35746[[#This Row],[現在値]] -> 0.029132948 | O9: =ROUND( ((IF(OR(R9="",R9<=0),20,R9)/20) *(L9/15)) /(IFERROR(IF(H9>0,H9,15),15)/15) *100,0) -> 134 | P9: =ROUND( ((IF(OR(R9="",R9<=0),20,R9)/20) *(L9/15) *((MIN(MAX(S9,0),50)/15)+1) *(1+MIN(MAX(IFERROR(IF(W9="",0,W9),0),-30),50)/200)) /(IFERROR(IF(H9>0,H9,15),15)/15) *100,0) -> 134 | Q9: =T20D35746[[#This Row],[スコア⑤]]/T20D35746[[#This Row],[スコア③]] -> 1 | W9: =(T20D35746[[#This Row],[現金及び預金（億）]]-T20D35746[[#This Row],[負債（億）]])/T20D35746[[#This Row],[総資産]]*100 -> #DIV/0!
A10: 3660 | B10: =IFERROR(_xll.RssMarket($A10,"銘柄名称"),"") -> アイスタイル | C10: =IFERROR(_xll.RssMarket($A10,"市場部略称"),"") -> 東Ｐ | D10: =IFERROR(_xll.RssMarket($A10,"現在値"),"") -> 448 | E10: =IFERROR(_xll.RssMarket($A10,"前日比"),"") -> -23 | F10: =IFERROR(_xll.RssMarket($A10,"時価総額"),"") -> 45918 | G10: =T20D35746[[#This Row],[時価総額]]/T20D35746[[#This Row],[現在値]] -> 102.49554 | H10: =IFERROR(_xll.RssMarket($A10,"PER"),"") -> 16.05 | I10: =T20D35746[[#This Row],[現在値]] / IFERROR(IF(T20D35746[[#This Row],[PER]] > 0, T20D35746[[#This Row],[PER]], 15), 15) -> 27.912773 | J10: =IFERROR(_xll.RssMarket($A10,"PBR"),"") -> 2.5 | K10: =T20D35746[[#This Row],[現在値]]/T20D35746[[#This Row],[PBR]] -> 179.2 | L10: =T20D35746[[#This Row],[EPS]]/T20D35746[[#This Row],[BPS]]*100 -> 15.576324 | M10: =IFERROR(_xll.RssMarket($A10,"配当"),"") -> 1 | N10: =T20D35746[[#This Row],[配当]]/T20D35746[[#This Row],[現在値]] -> 0.0022321429 | O10: =ROUND( ((IF(OR(R10="",R10<=0),20,R10)/20) *(L10/15)) /(IFERROR(IF(H10>0,H10,15),15)/15) *100,0) -> 97 | P10: =ROUND( ((IF(OR(R10="",R10<=0),20,R10)/20) *(L10/15) *((MIN(MAX(S10,0),50)/15)+1) *(1+MIN(MAX(IFERROR(IF(W10="",0,W10),0),-30),50)/200)) /(IFERROR(IF(H10>0,H10,15),15)/15) *100,0) -> 97 | Q10: =T20D35746[[#This Row],[スコア⑤]]/T20D35746[[#This Row],[スコア③]] -> 1 | W10: =(T20D35746[[#This Row],[現金及び預金（億）]]-T20D35746[[#This Row],[負債（億）]])/T20D35746[[#This Row],[総資産]]*100 -> #DIV/0!
A11: 3687 | B11: =IFERROR(_xll.RssMarket($A11,"銘柄名称"),"") -> フィックスターズ | C11: =IFERROR(_xll.RssMarket($A11,"市場部略称"),"") -> 東Ｐ | D11: =IFERROR(_xll.RssMarket($A11,"現在値"),"") -> 1444 | E11: =IFERROR(_xll.RssMarket($A11,"前日比"),"") -> -38 | F11: =IFERROR(_xll.RssMarket($A11,"時価総額"),"") -> 48568 | G11: =T20D35746[[#This Row],[時価総額]]/T20D35746[[#This Row],[現在値]] -> 33.634349 | H11: =IFERROR(_xll.RssMarket($A11,"PER"),"") -> 29.17 | I11: =T20D35746[[#This Row],[現在値]] / IFERROR(IF(T20D35746[[#This Row],[PER]] > 0, T20D35746[[#This Row],[PER]], 15), 15) -> 49.502914 | J11: =IFERROR(_xll.RssMarket($A11,"PBR"),"") -> 5.64 | K11: =T20D35746[[#This Row],[現在値]]/T20D35746[[#This Row],[PBR]] -> 256.02837 | L11: =T20D35746[[#This Row],[EPS]]/T20D35746[[#This Row],[BPS]]*100 -> 19.334933 | M11: =IFERROR(_xll.RssMarket($A11,"配当"),"") -> 18 | N11: =T20D35746[[#This Row],[配当]]/T20D35746[[#This Row],[現在値]] -> 0.012465374 | O11: =ROUND( ((IF(OR(R11="",R11<=0),20,R11)/20) *(L11/15)) /(IFERROR(IF(H11>0,H11,15),15)/15) *100,0) -> 66 | P11: =ROUND( ((IF(OR(R11="",R11<=0),20,R11)/20) *(L11/15) *((MIN(MAX(S11,0),50)/15)+1) *(1+MIN(MAX(IFERROR(IF(W11="",0,W11),0),-30),50)/200)) /(IFERROR(IF(H11>0,H11,15),15)/15) *100,0) -> 66 | Q11: =T20D35746[[#This Row],[スコア⑤]]/T20D35746[[#This Row],[スコア③]] -> 1 | W11: =(T20D35746[[#This Row],[現金及び預金（億）]]-T20D35746[[#This Row],[負債（億）]])/T20D35746[[#This Row],[総資産]]*100 -> #DIV/0!
A12: 3698 | B12: =IFERROR(_xll.RssMarket($A12,"銘柄名称"),"") -> ＣＲＩ・ミドルウェア | C12: =IFERROR(_xll.RssMarket($A12,"市場部略称"),"") -> 東Ｓ | D12: =IFERROR(_xll.RssMarket($A12,"現在値"),"") -> 982 | E12: =IFERROR(_xll.RssMarket($A12,"前日比"),"") -> -82 | F12: =IFERROR(_xll.RssMarket($A12,"時価総額"),"") -> 5477 | G12: =T20D35746[[#This Row],[時価総額]]/T20D35746[[#This Row],[現在値]] -> 5.5773931 | H12: =IFERROR(_xll.RssMarket($A12,"PER"),"") -> 11.15 | I12: =T20D35746[[#This Row],[現在値]] / IFERROR(IF(T20D35746[[#This Row],[PER]] > 0, T20D35746[[#This Row],[PER]], 15), 15) -> 88.071749 | J12: =IFERROR(_xll.RssMarket($A12,"PBR"),"") -> 1.26 | K12: =T20D35746[[#This Row],[現在値]]/T20D35746[[#This Row],[PBR]] -> 779.36508 | L12: =T20D35746[[#This Row],[EPS]]/T20D35746[[#This Row],[BPS]]*100 -> 11.300448 | M12: =IFERROR(_xll.RssMarket($A12,"配当"),"") -> 27 | N12: =T20D35746[[#This Row],[配当]]/T20D35746[[#This Row],[現在値]] -> 0.027494908 | O12: =ROUND( ((IF(OR(R12="",R12<=0),20,R12)/20) *(L12/15)) /(IFERROR(IF(H12>0,H12,15),15)/15) *100,0) -> 101 | P12: =ROUND( ((IF(OR(R12="",R12<=0),20,R12)/20) *(L12/15) *((MIN(MAX(S12,0),50)/15)+1) *(1+MIN(MAX(IFERROR(IF(W12="",0,W12),0),-30),50)/200)) /(IFERROR(IF(H12>0,H12,15),15)/15) *100,0) -> 101 | Q12: =T20D35746[[#This Row],[スコア⑤]]/T20D35746[[#This Row],[スコア③]] -> 1 | W12: =(T20D35746[[#This Row],[現金及び預金（億）]]-T20D35746[[#This Row],[負債（億）]])/T20D35746[[#This Row],[総資産]]*100 -> #DIV/0!
A13: 3915 | B13: =IFERROR(_xll.RssMarket($A13,"銘柄名称"),"") -> テラスカイ | C13: =IFERROR(_xll.RssMarket($A13,"市場部略称"),"") -> 東Ｐ | D13: =IFERROR(_xll.RssMarket($A13,"現在値"),"") -> 1910 | E13: =IFERROR(_xll.RssMarket($A13,"前日比"),"") -> -78 | F13: =IFERROR(_xll.RssMarket($A13,"時価総額"),"") -> 24674 | G13: =T20D35746[[#This Row],[時価総額]]/T20D35746[[#This Row],[現在値]] -> 12.918325 | H13: =IFERROR(_xll.RssMarket($A13,"PER"),"") -> 18 | I13: =T20D35746[[#This Row],[現在値]] / IFERROR(IF(T20D35746[[#This Row],[PER]] > 0, T20D35746[[#This Row],[PER]], 15), 15) -> 106.11111 | J13: =IFERROR(_xll.RssMarket($A13,"PBR"),"") -> 2.14 | K13: =T20D35746[[#This Row],[現在値]]/T20D35746[[#This Row],[PBR]] -> 892.52336 | L13: =T20D35746[[#This Row],[EPS]]/T20D35746[[#This Row],[BPS]]*100 -> 11.888889 | M13: =IFERROR(_xll.RssMarket($A13,"配当"),"") -> 16 | N13: =T20D35746[[#This Row],[配当]]/T20D35746[[#This Row],[現在値]] -> 0.0083769634 | O13: =ROUND( ((IF(OR(R13="",R13<=0),20,R13)/20) *(L13/15)) /(IFERROR(IF(H13>0,H13,15),15)/15) *100,0) -> 66 | P13: =ROUND( ((IF(OR(R13="",R13<=0),20,R13)/20) *(L13/15) *((MIN(MAX(S13,0),50)/15)+1) *(1+MIN(MAX(IFERROR(IF(W13="",0,W13),0),-30),50)/200)) /(IFERROR(IF(H13>0,H13,15),15)/15) *100,0) -> 66 | Q13: =T20D35746[[#This Row],[スコア⑤]]/T20D35746[[#This Row],[スコア③]] -> 1 | W13: =(T20D35746[[#This Row],[現金及び預金（億）]]-T20D35746[[#This Row],[負債（億）]])/T20D35746[[#This Row],[総資産]]*100 -> #DIV/0!
A14: 4022 | B14: =IFERROR(_xll.RssMarket($A14,"銘柄名称"),"") -> ラサ工業 | C14: =IFERROR(_xll.RssMarket($A14,"市場部略称"),"") -> 東Ｐ | D14: =IFERROR(_xll.RssMarket($A14,"現在値"),"") -> 9260 | E14: =IFERROR(_xll.RssMarket($A14,"前日比"),"") -> 120 | F14: =IFERROR(_xll.RssMarket($A14,"時価総額"),"") -> 73563 | G14: =T20D35746[[#This Row],[時価総額]]/T20D35746[[#This Row],[現在値]] -> 7.9441685 | H14: =IFERROR(_xll.RssMarket($A14,"PER"),"") -> 19.03 | I14: =T20D35746[[#This Row],[現在値]] / IFERROR(IF(T20D35746[[#This Row],[PER]] > 0, T20D35746[[#This Row],[PER]], 15), 15) -> 486.60011 | J14: =IFERROR(_xll.RssMarket($A14,"PBR"),"") -> 2.43 | K14: =T20D35746[[#This Row],[現在値]]/T20D35746[[#This Row],[PBR]] -> 3810.6996 | L14: =T20D35746[[#This Row],[EPS]]/T20D35746[[#This Row],[BPS]]*100 -> 12.769312 | M14: =IFERROR(_xll.RssMarket($A14,"配当"),"") -> 145 | N14: =T20D35746[[#This Row],[配当]]/T20D35746[[#This Row],[現在値]] -> 0.015658747 | O14: =ROUND( ((IF(OR(R14="",R14<=0),20,R14)/20) *(L14/15)) /(IFERROR(IF(H14>0,H14,15),15)/15) *100,0) -> 67 | P14: =ROUND( ((IF(OR(R14="",R14<=0),20,R14)/20) *(L14/15) *((MIN(MAX(S14,0),50)/15)+1) *(1+MIN(MAX(IFERROR(IF(W14="",0,W14),0),-30),50)/200)) /(IFERROR(IF(H14>0,H14,15),15)/15) *100,0) -> 67 | Q14: =T20D35746[[#This Row],[スコア⑤]]/T20D35746[[#This Row],[スコア③]] -> 1 | W14: =(T20D35746[[#This Row],[現金及び預金（億）]]-T20D35746[[#This Row],[負債（億）]])/T20D35746[[#This Row],[総資産]]*100 -> #DIV/0!
A15: 4398 | B15: =IFERROR(_xll.RssMarket($A15,"銘柄名称"),"") -> ブロードバンドセキュリテ | C15: =IFERROR(_xll.RssMarket($A15,"市場部略称"),"") -> 東Ｓ | D15: =IFERROR(_xll.RssMarket($A15,"現在値"),"") -> 1361 | E15: =IFERROR(_xll.RssMarket($A15,"前日比"),"") -> -117 | F15: =IFERROR(_xll.RssMarket($A15,"時価総額"),"") -> 6253 | G15: =T20D35746[[#This Row],[時価総額]]/T20D35746[[#This Row],[現在値]] -> 4.5944159 | H15: =IFERROR(_xll.RssMarket($A15,"PER"),"") -> 12.98 | I15: =T20D35746[[#This Row],[現在値]] / IFERROR(IF(T20D35746[[#This Row],[PER]] > 0, T20D35746[[#This Row],[PER]], 15), 15) -> 104.85362 | J15: =IFERROR(_xll.RssMarket($A15,"PBR"),"") -> 2.82 | K15: =T20D35746[[#This Row],[現在値]]/T20D35746[[#This Row],[PBR]] -> 482.62411 | L15: =T20D35746[[#This Row],[EPS]]/T20D35746[[#This Row],[BPS]]*100 -> 21.725732 | M15: =IFERROR(_xll.RssMarket($A15,"配当"),"") -> 16 | N15: =T20D35746[[#This Row],[配当]]/T20D35746[[#This Row],[現在値]] -> 0.011756062 | O15: =ROUND( ((IF(OR(R15="",R15<=0),20,R15)/20) *(L15/15)) /(IFERROR(IF(H15>0,H15,15),15)/15) *100,0) -> 83 | P15: =ROUND( ((IF(OR(R15="",R15<=0),20,R15)/20) *(L15/15) *((MIN(MAX(S15,0),50)/15)+1) *(1+MIN(MAX(IFERROR(IF(W15="",0,W15),0),-30),50)/200)) /(IFERROR(IF(H15>0,H15,15),15)/15) *100,0) -> 83 | Q15: =T20D35746[[#This Row],[スコア⑤]]/T20D35746[[#This Row],[スコア③]] -> 1 | R15: 9.86 | W15: =(T20D35746[[#This Row],[現金及び預金（億）]]-T20D35746[[#This Row],[負債（億）]])/T20D35746[[#This Row],[総資産]]*100 -> #DIV/0!
A16: 4519 | B16: =IFERROR(_xll.RssMarket($A16,"銘柄名称"),"") -> 中外製薬 | C16: =IFERROR(_xll.RssMarket($A16,"市場部略称"),"") -> 東Ｐ | D16: =IFERROR(_xll.RssMarket($A16,"現在値"),"") -> 9280 | E16: =IFERROR(_xll.RssMarket($A16,"前日比"),"") -> 80 | F16: =IFERROR(_xll.RssMarket($A16,"時価総額"),"") -> 15581655 | G16: =T20D35746[[#This Row],[時価総額]]/T20D35746[[#This Row],[現在値]] -> 1679.0577 | H16: =IFERROR(_xll.RssMarket($A16,"PER"),"") -> 33.94 | I16: =T20D35746[[#This Row],[現在値]] / IFERROR(IF(T20D35746[[#This Row],[PER]] > 0, T20D35746[[#This Row],[PER]], 15), 15) -> 273.42369 | J16: =IFERROR(_xll.RssMarket($A16,"PBR"),"") -> 7.53 | K16: =T20D35746[[#This Row],[現在値]]/T20D35746[[#This Row],[PBR]] -> 1232.4037 | L16: =T20D35746[[#This Row],[EPS]]/T20D35746[[#This Row],[BPS]]*100 -> 22.186211 | M16: =IFERROR(_xll.RssMarket($A16,"配当"),"") -> 132 | N16: =T20D35746[[#This Row],[配当]]/T20D35746[[#This Row],[現在値]] -> 0.014224138 | O16: =ROUND( ((IF(OR(R16="",R16<=0),20,R16)/20) *(L16/15)) /(IFERROR(IF(H16>0,H16,15),15)/15) *100,0) -> 65 | P16: =ROUND( ((IF(OR(R16="",R16<=0),20,R16)/20) *(L16/15) *((MIN(MAX(S16,0),50)/15)+1) *(1+MIN(MAX(IFERROR(IF(W16="",0,W16),0),-30),50)/200)) /(IFERROR(IF(H16>0,H16,15),15)/15) *100,0) -> 65 | Q16: =T20D35746[[#This Row],[スコア⑤]]/T20D35746[[#This Row],[スコア③]] -> 1 | W16: =(T20D35746[[#This Row],[現金及び預金（億）]]-T20D35746[[#This Row],[負債（億）]])/T20D35746[[#This Row],[総資産]]*100 -> #DIV/0! | X16: 優良銘柄
A17: 4568 | B17: =IFERROR(_xll.RssMarket($A17,"銘柄名称"),"") -> 第一三共 | C17: =IFERROR(_xll.RssMarket($A17,"市場部略称"),"") -> 東Ｐ | D17: =IFERROR(_xll.RssMarket($A17,"現在値"),"") -> 2937.5 | E17: =IFERROR(_xll.RssMarket($A17,"前日比"),"") -> 31.5 | F17: =IFERROR(_xll.RssMarket($A17,"時価総額"),"") -> 5564654 | G17: =T20D35746[[#This Row],[時価総額]]/T20D35746[[#This Row],[現在値]] -> 1894.3503 | H17: =IFERROR(_xll.RssMarket($A17,"PER"),"") -> 18.84 | I17: =T20D35746[[#This Row],[現在値]] / IFERROR(IF(T20D35746[[#This Row],[PER]] > 0, T20D35746[[#This Row],[PER]], 15), 15) -> 155.91826 | J17: =IFERROR(_xll.RssMarket($A17,"PBR"),"") -> 3.29 | K17: =T20D35746[[#This Row],[現在値]]/T20D35746[[#This Row],[PBR]] -> 892.85714 | L17: =T20D35746[[#This Row],[EPS]]/T20D35746[[#This Row],[BPS]]*100 -> 17.462845 | M17: =IFERROR(_xll.RssMarket($A17,"配当"),"") -> 78 | N17: =T20D35746[[#This Row],[配当]]/T20D35746[[#This Row],[現在値]] -> 0.026553191 | O17: =ROUND( ((IF(OR(R17="",R17<=0),20,R17)/20) *(L17/15)) /(IFERROR(IF(H17>0,H17,15),15)/15) *100,0) -> 93 | P17: =ROUND( ((IF(OR(R17="",R17<=0),20,R17)/20) *(L17/15) *((MIN(MAX(S17,0),50)/15)+1) *(1+MIN(MAX(IFERROR(IF(W17="",0,W17),0),-30),50)/200)) /(IFERROR(IF(H17>0,H17,15),15)/15) *100,0) -> 93 | Q17: =T20D35746[[#This Row],[スコア⑤]]/T20D35746[[#This Row],[スコア③]] -> 1 | W17: =(T20D35746[[#This Row],[現金及び預金（億）]]-T20D35746[[#This Row],[負債（億）]])/T20D35746[[#This Row],[総資産]]*100 -> #DIV/0! | X17: 優良銘柄
A18: 4661 | B18: =IFERROR(_xll.RssMarket($A18,"銘柄名称"),"") -> オリエンタルランド | C18: =IFERROR(_xll.RssMarket($A18,"市場部略称"),"") -> 東Ｐ | D18: =IFERROR(_xll.RssMarket($A18,"現在値"),"") -> 2819 | E18: =IFERROR(_xll.RssMarket($A18,"前日比"),"") -> 5.5 | F18: =IFERROR(_xll.RssMarket($A18,"時価総額"),"") -> 5075470 | G18: =T20D35746[[#This Row],[時価総額]]/T20D35746[[#This Row],[現在値]] -> 1800.4505 | H18: =IFERROR(_xll.RssMarket($A18,"PER"),"") -> 37.88 | I18: =T20D35746[[#This Row],[現在値]] / IFERROR(IF(T20D35746[[#This Row],[PER]] > 0, T20D35746[[#This Row],[PER]], 15), 15) -> 74.419219 | J18: =IFERROR(_xll.RssMarket($A18,"PBR"),"") -> 4.49 | K18: =T20D35746[[#This Row],[現在値]]/T20D35746[[#This Row],[PBR]] -> 627.83964 | L18: =T20D35746[[#This Row],[EPS]]/T20D35746[[#This Row],[BPS]]*100 -> 11.853221 | M18: =IFERROR(_xll.RssMarket($A18,"配当"),"") -> 14 | N18: =T20D35746[[#This Row],[配当]]/T20D35746[[#This Row],[現在値]] -> 0.0049663001 | O18: =ROUND( ((IF(OR(R18="",R18<=0),20,R18)/20) *(L18/15)) /(IFERROR(IF(H18>0,H18,15),15)/15) *100,0) -> 36 | P18: =ROUND( ((IF(OR(R18="",R18<=0),20,R18)/20) *(L18/15) *((MIN(MAX(S18,0),50)/15)+1) *(1+MIN(MAX(IFERROR(IF(W18="",0,W18),0),-30),50)/200)) /(IFERROR(IF(H18>0,H18,15),15)/15) *100,0) -> 36 | Q18: =T20D35746[[#This Row],[スコア⑤]]/T20D35746[[#This Row],[スコア③]] -> 1 | R18: 23.08 | W18: =(T20D35746[[#This Row],[現金及び預金（億）]]-T20D35746[[#This Row],[負債（億）]])/T20D35746[[#This Row],[総資産]]*100 -> #DIV/0!
A19: 4784 | B19: =IFERROR(_xll.RssMarket($A19,"銘柄名称"),"") -> ＧＭＯインターネット | C19: =IFERROR(_xll.RssMarket($A19,"市場部略称"),"") -> 東Ｐ | D19: =IFERROR(_xll.RssMarket($A19,"現在値"),"") -> 804 | E19: =IFERROR(_xll.RssMarket($A19,"前日比"),"") -> -89 | F19: =IFERROR(_xll.RssMarket($A19,"時価総額"),"") -> 220857 | G19: =T20D35746[[#This Row],[時価総額]]/T20D35746[[#This Row],[現在値]] -> 274.69776 | H19: =IFERROR(_xll.RssMarket($A19,"PER"),"") -> 44.17 | I19: =T20D35746[[#This Row],[現在値]] / IFERROR(IF(T20D35746[[#This Row],[PER]] > 0, T20D35746[[#This Row],[PER]], 15), 15) -> 18.2024 | J19: =IFERROR(_xll.RssMarket($A19,"PBR"),"") -> 16.72 | K19: =T20D35746[[#This Row],[現在値]]/T20D35746[[#This Row],[PBR]] -> 48.086124 | L19: =T20D35746[[#This Row],[EPS]]/T20D35746[[#This Row],[BPS]]*100 -> 37.853747 | M19: =IFERROR(_xll.RssMarket($A19,"配当"),"") -> 18.2 | N19: =T20D35746[[#This Row],[配当]]/T20D35746[[#This Row],[現在値]] -> 0.022636816 | O19: =ROUND( ((IF(OR(R19="",R19<=0),20,R19)/20) *(L19/15)) /(IFERROR(IF(H19>0,H19,15),15)/15) *100,0) -> 86 | P19: =ROUND( ((IF(OR(R19="",R19<=0),20,R19)/20) *(L19/15) *((MIN(MAX(S19,0),50)/15)+1) *(1+MIN(MAX(IFERROR(IF(W19="",0,W19),0),-30),50)/200)) /(IFERROR(IF(H19>0,H19,15),15)/15) *100,0) -> 86 | Q19: =T20D35746[[#This Row],[スコア⑤]]/T20D35746[[#This Row],[スコア③]] -> 1 | W19: =(T20D35746[[#This Row],[現金及び預金（億）]]-T20D35746[[#This Row],[負債（億）]])/T20D35746[[#This Row],[総資産]]*100 -> #DIV/0!
A20: 5121 | B20: =IFERROR(_xll.RssMarket($A20,"銘柄名称"),"") -> 藤倉コンポジット | C20: =IFERROR(_xll.RssMarket($A20,"市場部略称"),"") -> 東Ｐ | D20: =IFERROR(_xll.RssMarket($A20,"現在値"),"") -> 2535 | E20: =IFERROR(_xll.RssMarket($A20,"前日比"),"") -> -47 | F20: =IFERROR(_xll.RssMarket($A20,"時価総額"),"") -> 50890 | G20: =T20D35746[[#This Row],[時価総額]]/T20D35746[[#This Row],[現在値]] -> 20.074951 | H20: =IFERROR(_xll.RssMarket($A20,"PER"),"") -> 13.1 | I20: =T20D35746[[#This Row],[現在値]] / IFERROR(IF(T20D35746[[#This Row],[PER]] > 0, T20D35746[[#This Row],[PER]], 15), 15) -> 193.51145 | J20: =IFERROR(_xll.RssMarket($A20,"PBR"),"") -> 1.35 | K20: =T20D35746[[#This Row],[現在値]]/T20D35746[[#This Row],[PBR]] -> 1877.7778 | L20: =T20D35746[[#This Row],[EPS]]/T20D35746[[#This Row],[BPS]]*100 -> 10.305344 | M20: =IFERROR(_xll.RssMarket($A20,"配当"),"") -> 66 | N20: =T20D35746[[#This Row],[配当]]/T20D35746[[#This Row],[現在値]] -> 0.026035503 | O20: =ROUND( ((IF(OR(R20="",R20<=0),20,R20)/20) *(L20/15)) /(IFERROR(IF(H20>0,H20,15),15)/15) *100,0) -> 48 | P20: =ROUND( ((IF(OR(R20="",R20<=0),20,R20)/20) *(L20/15) *((MIN(MAX(S20,0),50)/15)+1) *(1+MIN(MAX(IFERROR(IF(W20="",0,W20),0),-30),50)/200)) /(IFERROR(IF(H20>0,H20,15),15)/15) *100,0) -> 48 | Q20: =T20D35746[[#This Row],[スコア⑤]]/T20D35746[[#This Row],[スコア③]] -> 1 | R20: 12.29 | W20: =(T20D35746[[#This Row],[現金及び預金（億）]]-T20D35746[[#This Row],[負債（億）]])/T20D35746[[#This Row],[総資産]]*100 -> #DIV/0!
A21: 6013 | B21: =IFERROR(_xll.RssMarket($A21,"銘柄名称"),"") -> タクマ | C21: =IFERROR(_xll.RssMarket($A21,"市場部略称"),"") -> 東Ｐ | D21: =IFERROR(_xll.RssMarket($A21,"現在値"),"") -> 2602 | E21: =IFERROR(_xll.RssMarket($A21,"前日比"),"") -> -79 | F21: =IFERROR(_xll.RssMarket($A21,"時価総額"),"") -> 209556 | G21: =T20D35746[[#This Row],[時価総額]]/T20D35746[[#This Row],[現在値]] -> 80.53651 | H21: =IFERROR(_xll.RssMarket($A21,"PER"),"") -> 15.27 | I21: =T20D35746[[#This Row],[現在値]] / IFERROR(IF(T20D35746[[#This Row],[PER]] > 0, T20D35746[[#This Row],[PER]], 15), 15) -> 170.39948 | J21: =IFERROR(_xll.RssMarket($A21,"PBR"),"") -> 1.8 | K21: =T20D35746[[#This Row],[現在値]]/T20D35746[[#This Row],[PBR]] -> 1445.5556 | L21: =T20D35746[[#This Row],[EPS]]/T20D35746[[#This Row],[BPS]]*100 -> 11.787819 | M21: =IFERROR(_xll.RssMarket($A21,"配当"),"") -> 79 | N21: =T20D35746[[#This Row],[配当]]/T20D35746[[#This Row],[現在値]] -> 0.030361261 | O21: =ROUND( ((IF(OR(R21="",R21<=0),20,R21)/20) *(L21/15)) /(IFERROR(IF(H21>0,H21,15),15)/15) *100,0) -> 77 | P21: =ROUND( ((IF(OR(R21="",R21<=0),20,R21)/20) *(L21/15) *((MIN(MAX(S21,0),50)/15)+1) *(1+MIN(MAX(IFERROR(IF(W21="",0,W21),0),-30),50)/200)) /(IFERROR(IF(H21>0,H21,15),15)/15) *100,0) -> 77 | Q21: =T20D35746[[#This Row],[スコア⑤]]/T20D35746[[#This Row],[スコア③]] -> 1 | W21: =(T20D35746[[#This Row],[現金及び預金（億）]]-T20D35746[[#This Row],[負債（億）]])/T20D35746[[#This Row],[総資産]]*100 -> #DIV/0!
A22: 6039 | B22: =IFERROR(_xll.RssMarket($A22,"銘柄名称"),"") -> 日本動物高度医療 | C22: =IFERROR(_xll.RssMarket($A22,"市場部略称"),"") -> 東Ｇ | D22: =IFERROR(_xll.RssMarket($A22,"現在値"),"") -> 1304 | E22: =IFERROR(_xll.RssMarket($A22,"前日比"),"") -> -21 | F22: =IFERROR(_xll.RssMarket($A22,"時価総額"),"") -> 18765 | G22: =T20D35746[[#This Row],[時価総額]]/T20D35746[[#This Row],[現在値]] -> 14.390337 | H22: =IFERROR(_xll.RssMarket($A22,"PER"),"") -> 23.07 | I22: =T20D35746[[#This Row],[現在値]] / IFERROR(IF(T20D35746[[#This Row],[PER]] > 0, T20D35746[[#This Row],[PER]], 15), 15) -> 56.523624 | J22: =IFERROR(_xll.RssMarket($A22,"PBR"),"") -> 3.77 | K22: =T20D35746[[#This Row],[現在値]]/T20D35746[[#This Row],[PBR]] -> 345.88859 | L22: =T20D35746[[#This Row],[EPS]]/T20D35746[[#This Row],[BPS]]*100 -> 16.341569 | M22: =IFERROR(_xll.RssMarket($A22,"配当"),"") -> 8 | N22: =T20D35746[[#This Row],[配当]]/T20D35746[[#This Row],[現在値]] -> 0.0061349693 | O22: =ROUND( ((IF(OR(R22="",R22<=0),20,R22)/20) *(L22/15)) /(IFERROR(IF(H22>0,H22,15),15)/15) *100,0) -> 71 | P22: =ROUND( ((IF(OR(R22="",R22<=0),20,R22)/20) *(L22/15) *((MIN(MAX(S22,0),50)/15)+1) *(1+MIN(MAX(IFERROR(IF(W22="",0,W22),0),-30),50)/200)) /(IFERROR(IF(H22>0,H22,15),15)/15) *100,0) -> 71 | Q22: =T20D35746[[#This Row],[スコア⑤]]/T20D35746[[#This Row],[スコア③]] -> 1 | W22: =(T20D35746[[#This Row],[現金及び預金（億）]]-T20D35746[[#This Row],[負債（億）]])/T20D35746[[#This Row],[総資産]]*100 -> #DIV/0!
A23: 6653 | B23: =IFERROR(_xll.RssMarket($A23,"銘柄名称"),"") -> 正興電機製作所 | C23: =IFERROR(_xll.RssMarket($A23,"市場部略称"),"") -> 東Ｐ | D23: =IFERROR(_xll.RssMarket($A23,"現在値"),"") -> 2260 | E23: =IFERROR(_xll.RssMarket($A23,"前日比"),"") -> -471 | F23: =IFERROR(_xll.RssMarket($A23,"時価総額"),"") -> 31433 | G23: =T20D35746[[#This Row],[時価総額]]/T20D35746[[#This Row],[現在値]] -> 13.908407 | H23: =IFERROR(_xll.RssMarket($A23,"PER"),"") -> 15.28 | I23: =T20D35746[[#This Row],[現在値]] / IFERROR(IF(T20D35746[[#This Row],[PER]] > 0, T20D35746[[#This Row],[PER]], 15), 15) -> 147.90576 | J23: =IFERROR(_xll.RssMarket($A23,"PBR"),"") -> 1.82 | K23: =T20D35746[[#This Row],[現在値]]/T20D35746[[#This Row],[PBR]] -> 1241.7582 | L23: =T20D35746[[#This Row],[EPS]]/T20D35746[[#This Row],[BPS]]*100 -> 11.910995 | M23: =IFERROR(_xll.RssMarket($A23,"配当"),"") -> 50 | N23: =T20D35746[[#This Row],[配当]]/T20D35746[[#This Row],[現在値]] -> 0.022123894 | O23: =ROUND( ((IF(OR(R23="",R23<=0),20,R23)/20) *(L23/15)) /(IFERROR(IF(H23>0,H23,15),15)/15) *100,0) -> 78 | P23: =ROUND( ((IF(OR(R23="",R23<=0),20,R23)/20) *(L23/15) *((MIN(MAX(S23,0),50)/15)+1) *(1+MIN(MAX(IFERROR(IF(W23="",0,W23),0),-30),50)/200)) /(IFERROR(IF(H23>0,H23,15),15)/15) *100,0) -> 78 | Q23: =T20D35746[[#This Row],[スコア⑤]]/T20D35746[[#This Row],[スコア③]] -> 1 | W23: =(T20D35746[[#This Row],[現金及び預金（億）]]-T20D35746[[#This Row],[負債（億）]])/T20D35746[[#This Row],[総資産]]*100 -> #DIV/0!
A24: 7927 | B24: =IFERROR(_xll.RssMarket($A24,"銘柄名称"),"") -> ムトー精工 | C24: =IFERROR(_xll.RssMarket($A24,"市場部略称"),"") -> 東Ｓ | D24: =IFERROR(_xll.RssMarket($A24,"現在値"),"") -> 2336 | E24: =IFERROR(_xll.RssMarket($A24,"前日比"),"") -> -100 | F24: =IFERROR(_xll.RssMarket($A24,"時価総額"),"") -> 18079 | G24: =T20D35746[[#This Row],[時価総額]]/T20D35746[[#This Row],[現在値]] -> 7.7392979 | H24: =IFERROR(_xll.RssMarket($A24,"PER"),"") -> 9.27 | I24: =T20D35746[[#This Row],[現在値]] / IFERROR(IF(T20D35746[[#This Row],[PER]] > 0, T20D35746[[#This Row],[PER]], 15), 15) -> 251.99569 | J24: =IFERROR(_xll.RssMarket($A24,"PBR"),"") -> 0.86 | K24: =T20D35746[[#This Row],[現在値]]/T20D35746[[#This Row],[PBR]] -> 2716.2791 | L24: =T20D35746[[#This Row],[EPS]]/T20D35746[[#This Row],[BPS]]*100 -> 9.2772384 | M24: =IFERROR(_xll.RssMarket($A24,"配当"),"") -> 101 | N24: =T20D35746[[#This Row],[配当]]/T20D35746[[#This Row],[現在値]] -> 0.043236301 | O24: =ROUND( ((IF(OR(R24="",R24<=0),20,R24)/20) *(L24/15)) /(IFERROR(IF(H24>0,H24,15),15)/15) *100,0) -> 100 | P24: =ROUND( ((IF(OR(R24="",R24<=0),20,R24)/20) *(L24/15) *((MIN(MAX(S24,0),50)/15)+1) *(1+MIN(MAX(IFERROR(IF(W24="",0,W24),0),-30),50)/200)) /(IFERROR(IF(H24>0,H24,15),15)/15) *100,0) -> 100 | Q24: =T20D35746[[#This Row],[スコア⑤]]/T20D35746[[#This Row],[スコア③]] -> 1 | W24: =(T20D35746[[#This Row],[現金及び預金（億）]]-T20D35746[[#This Row],[負債（億）]])/T20D35746[[#This Row],[総資産]]*100 -> #DIV/0!
A25: 9031 | B25: =IFERROR(_xll.RssMarket($A25,"銘柄名称"),"") -> 西日本鉄道 | C25: =IFERROR(_xll.RssMarket($A25,"市場部略称"),"") -> 東Ｐ | D25: =IFERROR(_xll.RssMarket($A25,"現在値"),"") -> 3145 | E25: =IFERROR(_xll.RssMarket($A25,"前日比"),"") -> 108 | F25: =IFERROR(_xll.RssMarket($A25,"時価総額"),"") -> 249587 | G25: =T20D35746[[#This Row],[時価総額]]/T20D35746[[#This Row],[現在値]] -> 79.359936 | H25: =IFERROR(_xll.RssMarket($A25,"PER"),"") -> 9.49 | I25: =T20D35746[[#This Row],[現在値]] / IFERROR(IF(T20D35746[[#This Row],[PER]] > 0, T20D35746[[#This Row],[PER]], 15), 15) -> 331.40148 | J25: =IFERROR(_xll.RssMarket($A25,"PBR"),"") -> 0.92 | K25: =T20D35746[[#This Row],[現在値]]/T20D35746[[#This Row],[PBR]] -> 3418.4783 | L25: =T20D35746[[#This Row],[EPS]]/T20D35746[[#This Row],[BPS]]*100 -> 9.6944152 | M25: =IFERROR(_xll.RssMarket($A25,"配当"),"") -> 50 | N25: =T20D35746[[#This Row],[配当]]/T20D35746[[#This Row],[現在値]] -> 0.015898251 | O25: =ROUND( ((IF(OR(R25="",R25<=0),20,R25)/20) *(L25/15)) /(IFERROR(IF(H25>0,H25,15),15)/15) *100,0) -> 102 | P25: =ROUND( ((IF(OR(R25="",R25<=0),20,R25)/20) *(L25/15) *((MIN(MAX(S25,0),50)/15)+1) *(1+MIN(MAX(IFERROR(IF(W25="",0,W25),0),-30),50)/200)) /(IFERROR(IF(H25>0,H25,15),15)/15) *100,0) -> 102 | Q25: =T20D35746[[#This Row],[スコア⑤]]/T20D35746[[#This Row],[スコア③]] -> 1 | W25: =(T20D35746[[#This Row],[現金及び預金（億）]]-T20D35746[[#This Row],[負債（億）]])/T20D35746[[#This Row],[総資産]]*100 -> #DIV/0!
A26: 9503 | B26: =IFERROR(_xll.RssMarket($A26,"銘柄名称"),"") -> 関西電力 | C26: =IFERROR(_xll.RssMarket($A26,"市場部略称"),"") -> 東Ｐ | D26: =IFERROR(_xll.RssMarket($A26,"現在値"),"") -> 2745.5 | E26: =IFERROR(_xll.RssMarket($A26,"前日比"),"") -> 2 | F26: =IFERROR(_xll.RssMarket($A26,"時価総額"),"") -> 3061033 | G26: =T20D35746[[#This Row],[時価総額]]/T20D35746[[#This Row],[現在値]] -> 1114.9273 | H26: =IFERROR(_xll.RssMarket($A26,"PER"),"") -> 8.49 | I26: =T20D35746[[#This Row],[現在値]] / IFERROR(IF(T20D35746[[#This Row],[PER]] > 0, T20D35746[[#This Row],[PER]], 15), 15) -> 323.38045 | J26: =IFERROR(_xll.RssMarket($A26,"PBR"),"") -> 0.93 | K26: =T20D35746[[#This Row],[現在値]]/T20D35746[[#This Row],[PBR]] -> 2952.1505 | L26: =T20D35746[[#This Row],[EPS]]/T20D35746[[#This Row],[BPS]]*100 -> 10.954064 | M26: =IFERROR(_xll.RssMarket($A26,"配当"),"") -> 75 | N26: =T20D35746[[#This Row],[配当]]/T20D35746[[#This Row],[現在値]] -> 0.027317429 | O26: =ROUND( ((IF(OR(R26="",R26<=0),20,R26)/20) *(L26/15)) /(IFERROR(IF(H26>0,H26,15),15)/15) *100,0) -> 72 | P26: =ROUND( ((IF(OR(R26="",R26<=0),20,R26)/20) *(L26/15) *((MIN(MAX(S26,0),50)/15)+1) *(1+MIN(MAX(IFERROR(IF(W26="",0,W26),0),-30),50)/200)) /(IFERROR(IF(H26>0,H26,15),15)/15) *100,0) -> 72 | Q26: =T20D35746[[#This Row],[スコア⑤]]/T20D35746[[#This Row],[スコア③]] -> 1 | R26: 11.11 | W26: =(T20D35746[[#This Row],[現金及び預金（億）]]-T20D35746[[#This Row],[負債（億）]])/T20D35746[[#This Row],[総資産]]*100 -> #DIV/0!
